[2023-01-02T11:37:16.928+0000] {taskinstance.py:1087} INFO - Dependencies all met for <TaskInstance: nba-dag.load scheduled__2023-01-01T11:37:00+00:00 [queued]>
[2023-01-02T11:37:16.935+0000] {taskinstance.py:1087} INFO - Dependencies all met for <TaskInstance: nba-dag.load scheduled__2023-01-01T11:37:00+00:00 [queued]>
[2023-01-02T11:37:16.936+0000] {taskinstance.py:1283} INFO - 
--------------------------------------------------------------------------------
[2023-01-02T11:37:16.936+0000] {taskinstance.py:1284} INFO - Starting attempt 1 of 6
[2023-01-02T11:37:16.937+0000] {taskinstance.py:1285} INFO - 
--------------------------------------------------------------------------------
[2023-01-02T11:37:16.946+0000] {taskinstance.py:1304} INFO - Executing <Task(PythonOperator): load> on 2023-01-01 11:37:00+00:00
[2023-01-02T11:37:16.970+0000] {standard_task_runner.py:55} INFO - Started process 62 to run task
[2023-01-02T11:37:16.977+0000] {standard_task_runner.py:82} INFO - Running: ['***', 'tasks', 'run', 'nba-dag', 'load', 'scheduled__2023-01-01T11:37:00+00:00', '--job-id', '43', '--raw', '--subdir', 'DAGS_FOLDER/nba_dag.py', '--cfg-path', '/tmp/tmpxz8105l2']
[2023-01-02T11:37:16.985+0000] {standard_task_runner.py:83} INFO - Job 43: Subtask load
[2023-01-02T11:37:17.100+0000] {task_command.py:389} INFO - Running <TaskInstance: nba-dag.load scheduled__2023-01-01T11:37:00+00:00 [running]> on host 7b186f3dc822
[2023-01-02T11:37:17.162+0000] {taskinstance.py:1513} INFO - Exporting the following env vars:
AIRFLOW_CTX_DAG_OWNER=Javier Prieto
AIRFLOW_CTX_DAG_ID=nba-dag
AIRFLOW_CTX_TASK_ID=load
AIRFLOW_CTX_EXECUTION_DATE=2023-01-01T11:37:00+00:00
AIRFLOW_CTX_TRY_NUMBER=1
AIRFLOW_CTX_DAG_RUN_ID=scheduled__2023-01-01T11:37:00+00:00
[2023-01-02T11:37:23.428+0000] {taskinstance.py:1772} ERROR - Task failed with exception
Traceback (most recent call last):
  File "/home/airflow/.local/lib/python3.7/site-packages/airflow/operators/python.py", line 175, in execute
    return_value = self.execute_callable()
  File "/home/airflow/.local/lib/python3.7/site-packages/airflow/operators/python.py", line 192, in execute_callable
    return self.python_callable(*self.op_args, **self.op_kwargs)
  File "/opt/airflow/plugins/team_stats.py", line 462, in load
    pdf.image('data/images/wins_losses.png', 5, 4, 100)
  File "/home/airflow/.local/lib/python3.7/site-packages/fpdf/fpdf.py", line 150, in wrapper
    return fn(self, *args, **kwargs)
  File "/home/airflow/.local/lib/python3.7/site-packages/fpdf/fpdf.py", line 971, in image
    info=self._parsepng(name)
  File "/home/airflow/.local/lib/python3.7/site-packages/fpdf/fpdf.py", line 1772, in _parsepng
    f=open(name,'rb')
FileNotFoundError: [Errno 2] No such file or directory: 'data/images/wins_losses.png'
[2023-01-02T11:37:23.472+0000] {taskinstance.py:1327} INFO - Marking task as UP_FOR_RETRY. dag_id=nba-dag, task_id=load, execution_date=20230101T113700, start_date=20230102T113716, end_date=20230102T113723
[2023-01-02T11:37:23.494+0000] {standard_task_runner.py:105} ERROR - Failed to execute job 43 for task load ([Errno 2] No such file or directory: 'data/images/wins_losses.png'; 62)
[2023-01-02T11:37:23.567+0000] {local_task_job.py:159} INFO - Task exited with return code 1
[2023-01-02T11:37:23.624+0000] {taskinstance.py:2582} INFO - 0 downstream tasks scheduled from follow-on schedule check
