[2023-01-02T11:25:05.457+0000] {taskinstance.py:1087} INFO - Dependencies all met for <TaskInstance: nba-dag.pronostico_extract scheduled__2023-01-01T11:25:00+00:00 [queued]>
[2023-01-02T11:25:05.473+0000] {taskinstance.py:1087} INFO - Dependencies all met for <TaskInstance: nba-dag.pronostico_extract scheduled__2023-01-01T11:25:00+00:00 [queued]>
[2023-01-02T11:25:05.474+0000] {taskinstance.py:1283} INFO - 
--------------------------------------------------------------------------------
[2023-01-02T11:25:05.474+0000] {taskinstance.py:1284} INFO - Starting attempt 1 of 6
[2023-01-02T11:25:05.475+0000] {taskinstance.py:1285} INFO - 
--------------------------------------------------------------------------------
[2023-01-02T11:25:05.498+0000] {taskinstance.py:1304} INFO - Executing <Task(PythonOperator): pronostico_extract> on 2023-01-01 11:25:00+00:00
[2023-01-02T11:25:05.515+0000] {standard_task_runner.py:55} INFO - Started process 59 to run task
[2023-01-02T11:25:05.520+0000] {standard_task_runner.py:82} INFO - Running: ['***', 'tasks', 'run', 'nba-dag', 'pronostico_extract', 'scheduled__2023-01-01T11:25:00+00:00', '--job-id', '27', '--raw', '--subdir', 'DAGS_FOLDER/nba_dag.py', '--cfg-path', '/tmp/tmppxzh3lok']
[2023-01-02T11:25:05.522+0000] {standard_task_runner.py:83} INFO - Job 27: Subtask pronostico_extract
[2023-01-02T11:25:05.737+0000] {task_command.py:389} INFO - Running <TaskInstance: nba-dag.pronostico_extract scheduled__2023-01-01T11:25:00+00:00 [running]> on host 7b186f3dc822
[2023-01-02T11:25:05.905+0000] {taskinstance.py:1513} INFO - Exporting the following env vars:
AIRFLOW_CTX_DAG_OWNER=Javier Prieto
AIRFLOW_CTX_DAG_ID=nba-dag
AIRFLOW_CTX_TASK_ID=pronostico_extract
AIRFLOW_CTX_EXECUTION_DATE=2023-01-01T11:25:00+00:00
AIRFLOW_CTX_TRY_NUMBER=1
AIRFLOW_CTX_DAG_RUN_ID=scheduled__2023-01-01T11:25:00+00:00
[2023-01-02T11:25:06.211+0000] {taskinstance.py:1772} ERROR - Task failed with exception
Traceback (most recent call last):
  File "/home/airflow/.local/lib/python3.7/site-packages/airflow/operators/python.py", line 175, in execute
    return_value = self.execute_callable()
  File "/home/airflow/.local/lib/python3.7/site-packages/airflow/operators/python.py", line 192, in execute_callable
    return self.python_callable(*self.op_args, **self.op_kwargs)
  File "/opt/airflow/plugins/pronosticos.py", line 8, in extract
    open('data/pronosticos_etl/extracted.txt','w').write(text)
FileNotFoundError: [Errno 2] No such file or directory: 'data/pronosticos_etl/extracted.txt'
[2023-01-02T11:25:06.227+0000] {taskinstance.py:1327} INFO - Marking task as UP_FOR_RETRY. dag_id=nba-dag, task_id=pronostico_extract, execution_date=20230101T112500, start_date=20230102T112505, end_date=20230102T112506
[2023-01-02T11:25:06.269+0000] {standard_task_runner.py:105} ERROR - Failed to execute job 27 for task pronostico_extract ([Errno 2] No such file or directory: 'data/pronosticos_etl/extracted.txt'; 59)
[2023-01-02T11:25:06.310+0000] {local_task_job.py:159} INFO - Task exited with return code 1
[2023-01-02T11:25:06.350+0000] {taskinstance.py:2582} INFO - 0 downstream tasks scheduled from follow-on schedule check
