[2023-01-02T10:22:05.806+0000] {taskinstance.py:1087} INFO - Dependencies all met for <TaskInstance: nba-dag.load scheduled__2023-01-02T10:16:52.871548+00:00 [queued]>
[2023-01-02T10:22:05.813+0000] {taskinstance.py:1087} INFO - Dependencies all met for <TaskInstance: nba-dag.load scheduled__2023-01-02T10:16:52.871548+00:00 [queued]>
[2023-01-02T10:22:05.814+0000] {taskinstance.py:1283} INFO - 
--------------------------------------------------------------------------------
[2023-01-02T10:22:05.814+0000] {taskinstance.py:1284} INFO - Starting attempt 1 of 6
[2023-01-02T10:22:05.815+0000] {taskinstance.py:1285} INFO - 
--------------------------------------------------------------------------------
[2023-01-02T10:22:05.825+0000] {taskinstance.py:1304} INFO - Executing <Task(PythonOperator): load> on 2023-01-02 10:16:52.871548+00:00
[2023-01-02T10:22:05.837+0000] {standard_task_runner.py:55} INFO - Started process 68 to run task
[2023-01-02T10:22:05.842+0000] {standard_task_runner.py:82} INFO - Running: ['***', 'tasks', 'run', 'nba-dag', 'load', 'scheduled__2023-01-02T10:16:52.871548+00:00', '--job-id', '75', '--raw', '--subdir', 'DAGS_FOLDER/nba_dag.py', '--cfg-path', '/tmp/tmpl5nve0q2']
[2023-01-02T10:22:05.845+0000] {standard_task_runner.py:83} INFO - Job 75: Subtask load
[2023-01-02T10:22:05.909+0000] {task_command.py:389} INFO - Running <TaskInstance: nba-dag.load scheduled__2023-01-02T10:16:52.871548+00:00 [running]> on host 64c425265806
[2023-01-02T10:22:05.987+0000] {taskinstance.py:1513} INFO - Exporting the following env vars:
AIRFLOW_CTX_DAG_OWNER=Javier Prieto
AIRFLOW_CTX_DAG_ID=nba-dag
AIRFLOW_CTX_TASK_ID=load
AIRFLOW_CTX_EXECUTION_DATE=2023-01-02T10:16:52.871548+00:00
AIRFLOW_CTX_TRY_NUMBER=1
AIRFLOW_CTX_DAG_RUN_ID=scheduled__2023-01-02T10:16:52.871548+00:00
[2023-01-02T10:22:11.072+0000] {taskinstance.py:1772} ERROR - Task failed with exception
Traceback (most recent call last):
  File "/home/airflow/.local/lib/python3.7/site-packages/airflow/operators/python.py", line 175, in execute
    return_value = self.execute_callable()
  File "/home/airflow/.local/lib/python3.7/site-packages/airflow/operators/python.py", line 192, in execute_callable
    return self.python_callable(*self.op_args, **self.op_kwargs)
  File "/opt/airflow/plugins/team_stats.py", line 376, in load
    pdf.image(f'data/images/{file_name}.png', 5, 4, 20)
  File "/home/airflow/.local/lib/python3.7/site-packages/fpdf/fpdf.py", line 150, in wrapper
    return fn(self, *args, **kwargs)
  File "/home/airflow/.local/lib/python3.7/site-packages/fpdf/fpdf.py", line 971, in image
    info=self._parsepng(name)
  File "/home/airflow/.local/lib/python3.7/site-packages/fpdf/fpdf.py", line 1772, in _parsepng
    f=open(name,'rb')
FileNotFoundError: [Errno 2] No such file or directory: 'data/images/golden_state_warriors.png'
[2023-01-02T10:22:11.095+0000] {taskinstance.py:1327} INFO - Marking task as UP_FOR_RETRY. dag_id=nba-dag, task_id=load, execution_date=20230102T101652, start_date=20230102T102205, end_date=20230102T102211
[2023-01-02T10:22:11.118+0000] {standard_task_runner.py:105} ERROR - Failed to execute job 75 for task load ([Errno 2] No such file or directory: 'data/images/golden_state_warriors.png'; 68)
[2023-01-02T10:22:11.179+0000] {local_task_job.py:159} INFO - Task exited with return code 1
[2023-01-02T10:22:11.215+0000] {taskinstance.py:2582} INFO - 0 downstream tasks scheduled from follow-on schedule check
