[2023-01-01T20:08:36.609+0000] {taskinstance.py:1087} INFO - Dependencies all met for <TaskInstance: nba-dag.pronostico manual__2023-01-01T19:46:06.117940+00:00 [queued]>
[2023-01-01T20:08:36.642+0000] {taskinstance.py:1087} INFO - Dependencies all met for <TaskInstance: nba-dag.pronostico manual__2023-01-01T19:46:06.117940+00:00 [queued]>
[2023-01-01T20:08:36.644+0000] {taskinstance.py:1283} INFO - 
--------------------------------------------------------------------------------
[2023-01-01T20:08:36.646+0000] {taskinstance.py:1284} INFO - Starting attempt 3 of 6
[2023-01-01T20:08:36.648+0000] {taskinstance.py:1285} INFO - 
--------------------------------------------------------------------------------
[2023-01-01T20:08:36.681+0000] {taskinstance.py:1304} INFO - Executing <Task(PythonOperator): pronostico> on 2023-01-01 19:46:06.117940+00:00
[2023-01-01T20:08:36.722+0000] {standard_task_runner.py:55} INFO - Started process 63 to run task
[2023-01-01T20:08:36.787+0000] {standard_task_runner.py:82} INFO - Running: ['***', 'tasks', 'run', 'nba-dag', 'pronostico', 'manual__2023-01-01T19:46:06.117940+00:00', '--job-id', '11', '--raw', '--subdir', 'DAGS_FOLDER/nba_dag.py', '--cfg-path', '/tmp/tmpbzarvato']
[2023-01-01T20:08:36.791+0000] {standard_task_runner.py:83} INFO - Job 11: Subtask pronostico
[2023-01-01T20:08:37.142+0000] {task_command.py:389} INFO - Running <TaskInstance: nba-dag.pronostico manual__2023-01-01T19:46:06.117940+00:00 [running]> on host 8bde35a245c7
[2023-01-01T20:08:37.421+0000] {taskinstance.py:1513} INFO - Exporting the following env vars:
AIRFLOW_CTX_DAG_OWNER=Javier Prieto
AIRFLOW_CTX_DAG_ID=nba-dag
AIRFLOW_CTX_TASK_ID=pronostico
AIRFLOW_CTX_EXECUTION_DATE=2023-01-01T19:46:06.117940+00:00
AIRFLOW_CTX_TRY_NUMBER=3
AIRFLOW_CTX_DAG_RUN_ID=manual__2023-01-01T19:46:06.117940+00:00
[2023-01-01T20:08:37.445+0000] {taskinstance.py:1772} ERROR - Task failed with exception
Traceback (most recent call last):
  File "/home/airflow/.local/lib/python3.7/site-packages/airflow/operators/python.py", line 175, in execute
    return_value = self.execute_callable()
  File "/home/airflow/.local/lib/python3.7/site-packages/airflow/operators/python.py", line 192, in execute_callable
    return self.python_callable(*self.op_args, **self.op_kwargs)
TypeError: prediction() missing 1 required positional argument: 'team'
[2023-01-01T20:08:37.477+0000] {taskinstance.py:1327} INFO - Marking task as UP_FOR_RETRY. dag_id=nba-dag, task_id=pronostico, execution_date=20230101T194606, start_date=20230101T200836, end_date=20230101T200837
[2023-01-01T20:08:37.526+0000] {standard_task_runner.py:105} ERROR - Failed to execute job 11 for task pronostico (prediction() missing 1 required positional argument: 'team'; 63)
[2023-01-01T20:08:37.634+0000] {local_task_job.py:159} INFO - Task exited with return code 1
[2023-01-01T20:08:37.779+0000] {taskinstance.py:2582} INFO - 0 downstream tasks scheduled from follow-on schedule check
